Workbook

Sheet M&A & Financial metrics
D1: Profitability Ratio | H1: Liquidity Ratio | K1: Solvency Ratio
A2: Year t | B2: Number of Acquisitions t | C2: Amount spent for acquistion ($) | D2: ROA t (%) | E2: ROE t (%) | F2: Net profit margin (%) | G2: ESP basics (US $) | H2: Current Ratio (%) | I2: Quick Ratio (%) | J2: Cash ratio (%) | K2: Total Debt/Total Assets (%) | L2: Total Debt/ Total Equity (%) | M2: Net debt/E (%) | N2: Revenue ($) | O2: Market capitalization ($)
A3: 2024 | B3: =SUMPRODUCT(('M&A Deals'!H:H = "Buyer") * (RIGHT('M&A Deals'!B:B, 2) = RIGHT(A3, 2))) -> 4 | C3: 2931000000 | D3: {=TRANSPOSE('Ratios Factset'!B18:V18)} -> 23,48 | E3: {=TRANSPOSE('Ratios Factset'!B19:V19)} -> 32,91 | F3: {=TRANSPOSE('Ratios Factset'!B15:V15)} -> 28,62 | G3: {=TRANSPOSE('Ratios Factset'!B40:V40)} -> 8,13 | H3: {=TRANSPOSE('Ratios Factset'!B86:V86)} -> 1,84 | I3: {=TRANSPOSE('Ratios Factset'!B87:V87)} -> 1,84 | J3: {=TRANSPOSE('Ratios Factset'!B88:V88)} -> 1,07 | K3: {=TRANSPOSE('Ratios Factset'!B112:V112)} -> 6,25 | L3: {=TRANSPOSE('Ratios Factset'!B114:V114)} -> 8,66 | M3: {=TRANSPOSE('Ratios Factset'!B113:V113)} -> -20,77 | N3: 349810000000 | O3: 2317220000000
A4: 2023 | B4: =SUMPRODUCT(('M&A Deals'!H:H = "Buyer") * (RIGHT('M&A Deals'!B:B, 2) = RIGHT(A4, 2))) -> 2 | C4: 495000000 | D4: 19,23 | E4: 27,36 | F4: 24,03 | G4: 5,84 | H4: 2,10 | I4: 2,10 | J4: 1,36 | K4: 7,42 | L4: 10,54 | M4: -28,60 | N4: 307160000000 | O4: 1748360000000
A5: 2022 | B5: =SUMPRODUCT(('M&A Deals'!H:H = "Buyer") * (RIGHT('M&A Deals'!B:B, 2) = RIGHT(A5, 2))) -> 16 | C5: 6969000000 | D5: 16,55 | E5: 23,62 | F5: 21,35 | G5: 4,59 | H5: 2,38 | I5: 2,34 | J5: 1,64 | K5: 8,21 | L5: 11,70 | M5: -32,71 | N5: 280880000000 | O5: 1141960000000
A6: 2021 | B6: =SUMPRODUCT(('M&A Deals'!H:H = "Buyer") * (RIGHT('M&A Deals'!B:B, 2) = RIGHT(A6, 2))) -> 15 | C6: 2618000000 | D6: 22,40 | E6: 32,07 | F6: 29,53 | G6: 5,69 | H6: 2,93 | I6: 2,91 | J6: 2,17 | K6: 7,94 | L6: 11,33 | M6: -44,17 | N6: 257490000000 | O6: 1922950000000
A7: 2020 | B7: =SUMPRODUCT(('M&A Deals'!H:H = "Buyer") * (RIGHT('M&A Deals'!B:B, 2) = RIGHT(A7, 2))) -> 10 | C7: 738000000 | D7: 13,52 | E7: 19,00 | F7: 22,08 | G7: 2,96 | H7: 3,07 | I7: 3,05 | J7: 2,41 | K7: 8,72 | L7: 12,52 | M7: -48,90 | N7: 182350000000 | O7: 1185830000000
A8: 2019 | B8: =SUMPRODUCT(('M&A Deals'!H:H = "Buyer") * (RIGHT('M&A Deals'!B:B, 2) = RIGHT(A8, 2))) -> 9 | C8: 2515000000 | D8: 13,50 | E8: 18,12 | F8: 21,28 | G8: 2,48 | H8: 3,37 | I8: 3,35 | J8: 2,65 | K8: 5,79 | L8: 7,93 | M8: -51,48 | N8: 161400000000 | O8: 923770000000
A9: 2018 | B9: =SUMPRODUCT(('M&A Deals'!H:H = "Buyer") * (RIGHT('M&A Deals'!B:B, 2) = RIGHT(A9, 2))) -> 15 | C9: 1491000000 | D9: 14,29 | E9: 18,62 | F9: 22,44 | G9: 2,21 | H9: 3,92 | I9: 3,89 | J9: 3,15 | K9: 1,72 | L9: 2,26 | M9: -59,18 | N9: 136960000000 | O9: 726730000000
A10: 2017 | B10: =SUMPRODUCT(('M&A Deals'!H:H = "Buyer") * (RIGHT('M&A Deals'!B:B, 2) = RIGHT(A10, 2))) -> 15 | C10: 287000000 | D10: 6,94 | E10: 8,69 | F10: 11,40 | G10: 0,91 | H10: 5,14 | I10: 5,11 | J10: 4,21 | K10: 2,01 | L10: 2,60 | M10: -64,20 | N10: 111020000000 | O10: 731900000000
A11: 2016 | B11: =SUMPRODUCT(('M&A Deals'!H:H = "Buyer") * (RIGHT('M&A Deals'!B:B, 2) = RIGHT(A11, 2))) -> 21 | C11: 986000000 | D11: 12,37 | E11: 15,02 | F11: 21,71 | G11: 1,42 | H11: 6,29 | I11: 6,27 | J11: 5,15 | K11: 2,35 | L11: 2,83 | M11: -59,26 | N11: 89730000000 | O11: 546190000000
A12: 2015 | B12: =SUMPRODUCT(('M&A Deals'!H:H = "Buyer") * (RIGHT('M&A Deals'!B:B, 2) = RIGHT(A12, 2))) -> 38 | C12: 236000000 | D12: 11,44 | E12: 14,12 | F12: 21,51 | G12: 1,16 | H12: 4,67 | I12: 4,64 | J12: 3,78 | K12: 3,54 | L12: 4,34 | M12: -56,38 | N12: 73590000000 | O12: 535060000000
A13: 2014 | B13: =SUMPRODUCT(('M&A Deals'!H:H = "Buyer") * (RIGHT('M&A Deals'!B:B, 2) = RIGHT(A13, 2))) -> 44 | C13: 4888000000 | D13: 11,34 | E13: 14,25 | F13: 20,69 | G13: 0,99 | H13: 4,69 | I13: 4,69 | J13: 3,84 | K13: 4,05 | L13: 5,04 | M13: -56,96 | N13: 65830000000 | O13: 359980000000
A14: 2013 | B14: =SUMPRODUCT(('M&A Deals'!H:H = "Buyer") * (RIGHT('M&A Deals'!B:B, 2) = RIGHT(A14, 2))) -> 21 | C14: 1448000000 | D14: 11,93 | E14: 15,36 | F14: 20,45 | G14: 0,91 | H14: 4,58 | I14: 4,55 | J14: 3,69 | K14: 4,73 | L14: 6,01 | M14: -61,24 | N14: 59730000000 | O14: 374790000000
A15: 2012 | B15: =SUMPRODUCT(('M&A Deals'!H:H = "Buyer") * (RIGHT('M&A Deals'!B:B, 2) = RIGHT(A15, 2))) -> 16 | C15: 10568000000 | D15: 12,97 | E15: 16,61 | F15: 21,59 | G15: 0,82 | H15: 4,22 | I15: 4,18 | J15: 3,35 | K15: 5,90 | L15: 7,72 | M15: -59,33 | N15: 49960000000 | O15: 231570000000
... A23: 2004 | B23: =SUMPRODUCT(('M&A Deals'!H:H = "Buyer") * (RIGHT('M&A Deals'!B:B, 2) = RIGHT(A23, 2))) -> 3 | C23: 58863000 | D23: 19,08 | E23: 22,57 | F23: 12,51 | G23: 0,05 | H23: 7,91 | I23: 7,91 | J23: 6,30 | K23: 0,06 | L23: 0,06 | M23: -73,11 | N23: 3190000000 | O23: 52770000000

Sheet Market Cap
A1: Market Cap History Alphabet Inc. (GOOGL)
A2: Date | B2: Market Cap | C2: % Change
A3: 45764 | B3: 1,842.64B | C3: -20.48%
A4: Dec 31, 2024 | B4: 2,317.22B | C4: 32.54%
A5: Dec 29, 2023 | B5: 1,748.36B | C5: 53.10%
A6: Dec 30, 2022 | B6: 1,141.96B | C6: -40.61%
A7: Dec 31, 2021 | B7: 1,922.95B | C7: 62.20%
A8: Dec 31, 2020 | B8: 1,185.53B | C8: 28.34%
A9: Dec 31, 2019 | B9: 923.77B | C9: 27.11%
A10: Dec 31, 2018 | B10: 726.73B | C10: -0.71%
A11: Dec 29, 2017 | B11: 731.90B | C11: 34.00%
A12: Dec 30, 2016 | B12: 546.19B | C12: 2.08%
A13: Dec 31, 2015 | B13: 535.06B | C13: 48.64%
A14: Dec 31, 2014 | B14: 359.98B | C14: -3.95%
A15: Dec 31, 2013 | B15: 374.79B | C15: 61.85%
... A24: Dec 31, 2004 | B24: 52.77B | C24: 93.71%
A25: Source: https://stockanalysis.com/stocks/googl/market-cap/

Sheet Income statement
A1: Alphabet Inc. Class C (GOOG)
A2: $149.11
A5: Alphabet Inc. Class C
A6: GOOG 02079K107 BYY88Y7 NASDAQ Common stock
A7: Source: FactSet Fundamentals
B8: DEC '24 | C8: DEC '23 | D8: DEC '22 | E8: DEC '21 | F8: DEC '20 | G8: DEC '19 | H8: DEC '18 | I8: DEC '17 | J8: DEC '16 | K8: DEC '15 | L8: DEC '14 | M8: DEC '13 | N8: DEC '12 | O8: DEC '11 | P8: DEC '10 | Q8: DEC '09 | R8: DEC '08 | S8: DEC '07 | T8: DEC '06 | U8: DEC '05 | V8: DEC '04 | W8: DEC '03 | X8: DEC '02 | Y8: DEC '01
K9: Restate | L9: Restate
A10: Sales | B10: 349.81 | C10: 307.16 | D10: 280.88 | E10: 257.49 | F10: 182.35 | G10: 161.4 | H10: 136.96 | I10: 111.02 | J10: 89.73 | K10: 73.59 | L10: 65.83 | M10: 59.73 | N10: 49.96 | O10: 37.86 | P10: 29.12 | Q10: 23.33 | R10: 21.8 | S10: 16.59 | T10: 10.6 | U10: 6.14 | V10: 3.19 | W10: 1.47 | X10: 0.44 | Y10: 0.09
A11: Growth (%) | B11: 13.89 | C11: 9.36 | D11: 9.08 | E11: 41.21 | F11: 12.98 | G11: 17.85 | H11: 23.36 | I11: 23.73 | J11: 21.94 | K11: 11.79 | L11: 10.21 | M11: 19.56 | N11: 31.95 | O11: 30.03 | P11: 24.83 | Q11: 7.02 | R11: 31.35 | S11: 56.47 | T11: 72.76 | U11: 92.48 | V11: 117.56 | W11: 233.54 | X11: 408.54
A12: Cost of Goods Sold (COGS) incl. D&A | B12: 146.31 | C12: 132.85 | D12: 126.2 | E12: 110.94 | F12: 84.73 | G12: 71.9 | H12: 59.55 | I12: 45.58 | J12: 35.14 | K12: 28.16 | L12: 25.31 | M12: 25.82 | N12: 20.51 | O12: 13.19 | P12: 10.42 | Q12: 8.84 | R12: 8.62 | S12: 6.65 | T12: 4.23 | U12: 2.57 | V12: 1.46 | W12: 0.63 | X12: 0.13 | Y12: 0.01
A13: COGS excluding D&A | B13: 131 | C13: 120.91 | D13: 110.28 | E13: 98.5 | F13: 71.04 | G13: 60.12 | H13: 50.51 | I13: 38.67 | J13: 28.99 | K13: 23.1 | L13: 20.71 | M13: 21.89 | N13: 17.54 | O13: 11.34 | P13: 9.02 | Q13: 7.32 | R13: 7.12 | S13: 5.68 | T13: 3.65 | U13: 2.28 | V13: 1.31 | W13: 0.58 | X13: 0.11 | Y13: 0
A14: Depreciation & Amortization Expense | B14: 15.31 | C14: 11.95 | D14: 15.93 | E14: 12.44 | F14: 13.7 | G14: 11.78 | H14: 9.04 | I14: 6.92 | J14: 6.14 | K14: 5.06 | L14: 4.6 | M14: 3.94 | N14: 2.96 | O14: 1.85 | P14: 1.4 | Q14: 1.52 | R14: 1.5 | S14: 0.97 | T14: 0.57 | U14: 0.29 | V14: 0.15 | W14: 0.05 | X14: 0.02 | Y14: 0.01
A15: Depreciation | B15: 15.31 | C15: 11.95 | D15: 15.29 | E15: 11.56 | F15: 12.91 | G15: 10.86 | H15: 8.16 | I15: 6.1 | J15: 5.27 | K15: 4.13 | L15: 3.52 | M15: 2.78 | N15: 1.99 | O15: 1.4 | P15: 1.07 | Q15: 1.24 | R15: 1.21 | S15: 0.81 | T15: 0.49 | U15: 0.26 | V15: 0.13 | W15: 0.04 | X15: 0.02 | Y15: 0.01
A16: Amortization of Intangibles | B16: 0 | C16: 0 | D16: 0.64 | E16: 0.89 | F16: 0.79 | G16: 0.93 | H16: 0.87 | I16: 0.81 | J16: 0.88 | K16: 0.93 | L16: 1.08 | M16: 1.16 | N16: 0.97 | O16: 0.46 | P16: 0.33 | Q16: 0.28 | R16: 0.29 | S16: 0.16 | T16: 0.08 | U16: 0.04 | V16: 0.02 | W16: 0.01 | X16: 0 | Y16: 0
A17: Gross Income | B17: 203.5 | C17: 174.3 | D17: 154.67 | E17: 146.55 | F17: 97.62 | G17: 89.51 | H17: 77.41 | I17: 65.44 | J17: 54.6 | K17: 45.43 | L17: 40.52 | M17: 33.91 | N17: 29.45 | O17: 24.67 | P17: 18.7 | Q17: 14.48 | R17: 13.17 | S17: 9.94 | T17: 6.38 | U17: 3.57 | V17: 1.73 | W17: 0.84 | X17: 0.31 | Y17: 0.07
A18: Growth (%) | B18: 16.75 | C18: 12.69 | D18: 5.54 | E18: 50.12 | F18: 9.06 | G18: 15.63 | H18: 18.29 | I18: 19.87 | J18: 20.18 | K18: 12.12 | L18: 19.5 | M18: 15.12 | N18: 19.37 | O18: 31.94 | P18: 29.14 | Q18: 9.93 | R18: 32.47 | S18: 55.88 | T18: 78.86 | U18: 106 | V18: 106.12 | W18: 172.76 | X18: 326.6
A19: Margin (%) | B19: 58.18 | C19: 56.75 | D19: 55.07 | E19: 56.91 | F19: 53.53 | G19: 55.46 | H19: 56.52 | I19: 58.94 | J19: 60.84 | K19: 61.73 | L19: 61.55 | M19: 56.77 | N19: 58.96 | O19: 65.17 | P19: 64.22 | Q19: 62.08 | R19: 60.44 | S19: 59.93 | T19: 60.16 | U19: 58.11 | V19: 54.29 | W19: 57.31 | X19: 70.08 | Y19: 83.54
A20: SG&A Expense | B20: 91.32 | C20: 88.16 | D20: 81.79 | E20: 67.98 | F20: 56.57 | G20: 54.03 | H20: 45.88 | I20: 36.39 | J20: 31.42 | K20: 27.47 | L20: 23.81 | M20: 19.91 | N20: 16.33 | O20: 12.48 | P20: 8.52 | Q20: 6.49 | R20: 6.54 | S20: 4.86 | T20: 2.79 | U20: 1.44 | V20: 0.88 | W20: 0.5 | X20: 0.1 | Y20: 0.05
A21: Research & Development | B21: 49.33 | C21: 44.58 | D21: 39.5 | E21: 31.56 | F21: 27.57 | G21: 26.02 | H21: 21.42 | I21: 16.63 | J21: 13.95 | K21: 12.28 | L21: 9.83 | M21: 7.91 | N21: 6.59 | O21: 5.16 | P21: 3.76 | Q21: 2.84 | R21: 2.79 | S21: 2.12 | T21: 1.22 | U21: 0.46 | V21: 0.21 | W21: 0.09 | X21: 0.03 | Y21: 0.02
A22: Other SG&A | B22: 42 | C22: 43.58 | D22: 42.29 | E22: 36.42 | F22: 29 | G22: 28.02 | H22: 24.46 | I22: 19.77 | J22: 17.47 | K22: 15.18 | L22: 13.98 | M22: 12 | N22: 9.74 | O22: 7.31 | P22: 4.76 | Q22: 3.65 | R22: 3.75 | S22: 2.74 | T22: 1.57 | U22: 0.98 | V22: 0.66 | W22: 0.41 | X22: 0.07 | Y22: 0.03
A23: Other Operating Expense | B23: 0 | C23: 0 | D23: 0 | E23: 0 | F23: 0 | G23: 0 | H23: 0 | I23: 0 | J23: 0 | K23: 0 | L23: 0 | M23: 0 | N23: 0 | O23: 0 | P23: 0 | Q23: 0 | R23: 0 | S23: 0 | T23: 0 | U23: 0.09 | V23: 0 | W23: 0 | X23: 0.02 | Y23: 0.01
A24: EBIT (Operating Income) | B24: 112.18 | C24: 86.14 | D24: 72.88 | E24: 78.57 | F24: 41.05 | G24: 35.47 | H24: 31.53 | I24: 29.05 | J24: 23.18 | K24: 17.96 | L24: 16.7 | M24: 13.99 | N24: 13.12 | O24: 12.2 | P24: 10.18 | Q24: 7.99 | R24: 6.63 | S24: 5.08 | T24: 3.59 | U24: 2.04 | V24: 0.85 | W24: 0.34 | X24: 0.19 | Y24: 0.01
A25: Growth (%) | B25: 30.22 | C25: 18.2 | D25: -7.23 | E25: 91.4 | F25: 15.71 | G25: 12.5 | H25: 8.54 | I25: 25.34 | J25: 29.04 | K25: 7.53 | L25: 19.36 | M25: 6.67 | N25: 7.54 | O25: 19.86 | P25: 27.42 | Q25: 20.44 | R25: 30.44 | S25: 41.6 | T25: 76.08 | U25: 139.2 | V25: 148.95 | W25: 83.66 | X25: 1599.73
A26: Margin (%) | B26: 32.07 | C26: 28.05 | D26: 25.95 | E26: 30.51 | F26: 22.51 | G26: 21.98 | H26: 23.02 | I26: 26.17 | J26: 25.83 | K26: 24.41 | L26: 25.37 | M26: 23.43 | N26: 26.26 | O26: 32.22 | P26: 34.95 | Q26: 34.24 | R26: 30.43 | S26: 30.64 | T26: 33.86 | U26: 33.22 | V26: 26.73 | W26: 23.36 | X26: 42.43 | Y26: 12.69
A27: Nonoperating Income - Net | B27: 3.68 | C27: 2.03 | D27: 2.11 | E27: 2.12 | F27: 2.01 | G27: 3.06 | H27: 4.4 | I27: 1.11 | J27: 1.47 | K27: 2.1 | L27: 1.21 | M27: 0.6 | N27: 1.46 | O27: 1.12 | P27: 0.98 | Q27: 0.47 | R27: 0.32 | S27: 0.59 | T27: 0.46 | U27: 0.13 | V27: 0.01 | W27: 0.01 | X27: 0 | Y27: 0
A28: Nonoperating Interest Income | B28: 4.48 | C28: 3.87 | D28: 2.17 | E28: 1.5 | F28: 1.87 | G28: 2.43 | H28: 1.88 | I28: 1.31 | J28: 1.22 | K28: 1 | L28: 0.75 | M28: 0.79 | N28: 0.71 | O28: 0.81 | P28: 0.58 | Q28: 0.23 | R28: 0.39 | S28: 0.56 | T28: 0.41 | U28: 0.12 | V28: 0.02 | W28: 0 | X28: 0 | Y28: 0
A29: Equity in Earnings of Affiliates | B29: -0.19 | C29: -0.63 | D29: -0.34 | E29: 0.33 | F29: 0.4 | G29: 0.39 | H29: -0.12 | I29: -0.16 | J29: -0.2 | K29: -0.23 | N29: 0 | O29: 0 | P29: 0 | Q29: 0 | R29: 0 | S29: 0 | T29: 0 | U29: 0 | W29: 0 | X29: 0 | Y29: 0
A30: Reserves Increase (Decrease) | B30: 0 | C30: 0 | D30: 0 | E30: 0 | F30: 0 | G30: 0 | H30: 0 | I30: 0 | J30: 0 | K30: 0 | L30: 0 | M30: 0 | N30: 0 | O30: 0 | P30: 0 | Q30: 0 | R30: 0 | S30: 0 | T30: 0 | U30: 0 | V30: 0 | W30: 0 | X30: 0 | Y30: 0
A31: Other Income (Expense) | B31: -0.61 | C31: -1.2 | D31: 0.27 | E31: 0.28 | F31: -0.26 | G31: 0.24 | H31: 2.64 | I31: -0.05 | J31: 0.45 | K31: 1.32 | L31: 0.47 | M31: -0.19 | N31: 0.74 | O31: 0.31 | P31: 0.41 | Q31: 0.24 | R31: -0.07 | S31: 0.03 | T31: 0.05 | U31: 0 | V31: -0.01 | W31: 0 | X31: 0 | Y31: 0
A32: Interest Expense | B32: 0.27 | C32: 0.31 | D32: 0.36 | E32: 0.35 | F32: 0.14 | G32: 0.1 | H32: 0.11 | I32: 0.11 | J32: 0.12 | K32: 0.1 | L32: 0.1 | M32: 0.08 | N32: 0.08 | O32: 0.06 | P32: 0 | Q32: 0 | R32: 0 | S32: 0 | T32: 0 | U32: 0 | V32: 0 | W32: 0 | X32: 0 | Y32: 0
A33: Gross Interest Expense | B33: 0.46 | C33: 0.49 | D33: 0.49 | E33: 0.51 | F33: 0.35 | G33: 0.27 | H33: 0.21 | I33: 0.16 | J33: 0.12 | K33: 0.1 | L33: 0.1 | M33: 0.08 | N33: 0.08 | O33: 0.06 | P33: 0 | Q33: 0 | R33: 0 | S33: 0 | T33: 0 | U33: 0 | V33: 0 | W33: 0 | X33: 0 | Y33: 0
A34: Interest Capitalized | B34: 0.19 | C34: 0.18 | D34: 0.13 | E34: 0.16 | F34: 0.22 | G34: 0.17 | H34: 0.09 | I34: 0.05 | J34: 0 | K34: 0 | L34: 0 | M34: 0 | N34: 0 | O34: 0 | P34: 0 | Q34: 0 | R34: 0 | S34: 0 | T34: 0 | U34: 0 | V34: 0 | W34: 0 | Y34: 0
A35: Unusual Expense - Net | B35: -4.22 | C35: 2.15 | D35: 3.31 | E35: -10.4 | F35: -5.16 | G35: -1.2 | H35: 0.9 | I35: 2.86 | J35: 0.38 | K35: 0.3 | L35: 0.56 | M35: 0.01 | N35: 1.1 | O35: 0.94 | P35: 0.37 | Q35: 0.08 | R35: 1.09 | S35: 0 | T35: 0.04 | U35: 0.02 | V35: 0.21
A36: Impairments | L36: 0.38 | M36: 0 | N36: 0 | O36: 0.11 | P36: 0 | Q36: 0 | R36: 1.09
A37: Other Intangibles | B37: 0 | C37: 0 | D37: 0 | E37: 0 | F37: 0 | G37: 0 | H37: 0 | I37: 0 | J37: 0 | K37: 0 | L37: 0.38 | M37: 0 | N37: 0 | O37: 0 | P37: 0 | Q37: 0 | R37: 0 | S37: 0 | T37: 0 | U37: 0
A38: Financial Fixed Assets | M38: 0 | N38: 0 | O38: 0.11 | P38: 0 | Q38: 0 | R38: 1.09
A39: Restructuring Expense | B39: 0 | C39: 2.09 | D39: 0 | E39: 0 | F39: 0 | G39: 0 | H39: 0 | I39: 0 | J39: 0 | K39: 0 | L39: 0 | M39: 0.12 | N39: 0.58 | O39: 0 | P39: 0 | Q39: 0 | R39: 0 | S39: 0 | T39: 0 | U39: 0 | V39: 0 | W39: 0 | X39: 0 | Y39: 0
A40: Legal Claim Expense | E40: 0 | F40: 0 | G40: 1.7 | H40: 5.07 | I40: 2.74 | M40: 0 | N40: 0 | O40: 0.5 | T40: 0.03 | U40: 0 | V40: 0.2
A41: Unrealized Valuation Gain/Loss | B41: 4.22 | C41: -0.07 | D41: -3.31 | E41: 10.4 | F41: 5.16 | G41: 2.89 | H41: 4.17 | I41: -0.12 | J41: -0.38 | K41: -0.3 | L41: -0.18 | M41: 0.11 | N41: -0.53 | O41: -0.33 | P41: -0.37 | Q41: -0.08
A42: Investments | B42: 3.53 | C42: -0.3 | D42: -3.01 | E42: 11.18 | F42: 4.25 | G42: 2.95 | H42: 4
...

Sheet Key financial items
A1: Alphabet Inc. Class C (GOOG)
A2: $149.14
A5: Alphabet Inc. Class C
A6: GOOG 02079K107 BYY88Y7 NASDAQ Common stock
A7: Source: FactSet Fundamentals
B8: DEC '24 | C8: DEC '23 | D8: DEC '22 | E8: DEC '21 | F8: DEC '20 | G8: DEC '19 | H8: DEC '18 | I8: DEC '17 | J8: DEC '16 | K8: DEC '15 | L8: DEC '14 | M8: DEC '13 | N8: DEC '12 | O8: DEC '11 | P8: DEC '10 | Q8: DEC '09 | R8: DEC '08 | S8: DEC '07 | T8: DEC '06 | U8: DEC '05 | V8: DEC '04 | W8: DEC '03 | X8: DEC '02 | Y8: DEC '01
K9: Restate | L9: Restate
A10: Income Statement
A11: Sales | B11: 349.81 | C11: 307.16 | D11: 280.88 | E11: 257.49 | F11: 182.35 | G11: 161.4 | H11: 136.96 | I11: 111.02 | J11: 89.73 | K11: 73.59 | L11: 65.83 | M11: 59.73 | N11: 49.96 | O11: 37.86 | P11: 29.12 | Q11: 23.33 | R11: 21.8 | S11: 16.59 | T11: 10.6 | U11: 6.14 | V11: 3.19 | W11: 1.47 | X11: 0.44 | Y11: 0.09
A12: Gross Income | B12: 203.5 | C12: 174.3 | D12: 154.67 | E12: 146.55 | F12: 97.62 | G12: 89.51 | H12: 77.41 | I12: 65.44 | J12: 54.6 | K12: 45.43 | L12: 40.52 | M12: 33.91 | N12: 29.45 | O12: 24.67 | P12: 18.7 | Q12: 14.48 | R12: 13.17 | S12: 9.94 | T12: 6.38 | U12: 3.57 | V12: 1.73 | W12: 0.84 | X12: 0.31 | Y12: 0.07
A13: EBIT | B13: 112.18 | C13: 86.14 | D13: 72.88 | E13: 78.57 | F13: 41.05 | G13: 35.47 | H13: 31.53 | I13: 29.05 | J13: 23.18 | K13: 17.96 | L13: 16.7 | M13: 13.99 | N13: 13.12 | O13: 12.2 | P13: 10.18 | Q13: 7.99 | R13: 6.63 | S13: 5.08 | T13: 3.59 | U13: 2.04 | V13: 0.85 | W13: 0.34 | X13: 0.19 | Y13: 0.01
A14: EBITDA | B14: 127.49 | C14: 98.09 | D14: 88.81 | E14: 91.01 | F14: 54.74 | G14: 47.25 | H14: 40.57 | I14: 35.97 | J14: 29.32 | K14: 23.02 | L14: 21.31 | M14: 17.93 | N14: 16.08 | O14: 14.05 | P14: 11.57 | Q14: 9.51 | R14: 8.13 | S14: 6.05 | T14: 4.16 | U14: 2.33 | V14: 1 | W14: 0.39 | X14: 0.2 | Y14: 0.02
A15: Net Income | B15: 100.12 | C15: 73.8 | D15: 59.97 | E15: 76.03 | F15: 40.27 | G15: 34.34 | H15: 30.74 | I15: 12.66 | J15: 19.48 | K15: 15.83 | L15: 13.62 | M15: 12.21 | N15: 10.79 | O15: 9.74 | P15: 8.51 | Q15: 6.52 | R15: 4.23 | S15: 4.2 | T15: 3.08 | U15: 1.47 | V15: 0.4 | W15: 0.11 | X15: 0.1 | Y15: 0.01
A16: Balance Sheet
A17: Cash & Short-Term Investments | B17: 95.66 | C17: 110.92 | D17: 113.76 | E17: 139.65 | F17: 136.69 | G17: 119.68 | H17: 109.14 | I17: 101.87 | J17: 86.33 | K17: 73.07 | L17: 64.4 | M17: 58.72 | N17: 48.09 | O17: 44.63 | P17: 34.98 | Q17: 24.48 | R17: 15.85 | S17: 14.22 | T17: 11.24 | U17: 8.03 | V17: 2.14 | W17: 0.33 | X17: 0.15 | Y17: 0.03
A18: Total Assets | B18: 450.26 | C18: 402.39 | D18: 365.26 | E18: 359.27 | F18: 319.62 | G18: 275.91 | H18: 232.79 | I18: 197.3 | J18: 167.5 | K18: 147.46 | L18: 129.19 | M18: 110.92 | N18: 93.8 | O18: 72.57 | P18: 57.85 | Q18: 40.5 | R18: 31.77 | S18: 25.34 | T18: 18.47 | U18: 10.27 | V18: 3.3 | W18: 0.88 | X18: 0.29 | Y18: 0.08
A19: Total Debt | B19: 28.14 | C19: 29.87 | D19: 29.98 | E19: 28.51 | F19: 27.87 | G19: 15.97 | H19: 4.01 | I19: 3.97 | J19: 3.94 | K19: 5.22 | L19: 5.24 | M19: 5.25 | N19: 5.54 | O19: 4.2 | P19: 3.47 | Q19: 0 | R19: 0 | S19: 0 | T19: 0 | U19: 0 | V19: 0 | W19: 0.01 | X19: 0.01
A20: Net Debt | B20: -67.52 | C20: -81.05 | D20: -83.79 | E20: -111.14 | F20: -108.82 | G20: -103.71 | H20: -105.13 | I20: -97.9 | J20: -82.4 | K20: -67.85 | L20: -59.16 | M20: -53.47 | N20: -42.55 | O20: -40.42 | P20: -31.51 | Q20: -24.48 | R20: -15.85 | S20: -14.22 | T20: -11.24 | U20: -8.03 | V20: -2.14 | W20: -0.33 | X20: -0.14
A21: Total Liabilities | B21: 125.17 | C21: 119.01 | D21: 109.12 | E21: 107.63 | F21: 97.07 | G21: 74.47 | H21: 55.16 | I21: 44.79 | J21: 28.46 | K21: 27.13 | L21: 25.33 | M21: 23.61 | N21: 22.08 | O21: 14.43 | P21: 11.61 | Q21: 4.49 | R21: 3.53 | S21: 2.65 | T21: 1.43 | U21: 0.85 | V21: 0.37 | W21: 0.27 | X21: 0.1 | Y21: 0.03
A22: Total Shareholders' Equity | B22: 325.08 | C22: 283.38 | D22: 256.14 | E22: 251.64 | F22: 222.54 | G22: 201.44 | H22: 177.63 | I22: 152.5 | J22: 139.04 | K22: 120.33 | L22: 103.86 | M22: 87.31 | N22: 71.72 | O22: 58.15 | P22: 46.24 | Q22: 36 | R22: 28.24 | S22: 22.69 | T22: 17.04 | U22: 9.42 | V22: 2.93 | W22: 0.61 | X22: 0.19 | Y22: 0.05
A23: Cash Flow
A24: Net Operating Cash Flow | B24: 125.3 | C24: 101.75 | D24: 91.5 | E24: 91.65 | F24: 65.12 | G24: 54.52 | H24: 47.97 | I24: 37.09 | J24: 36.04 | K24: 26.57 | L24: 22.38 | M24: 18.66 | N24: 16.62 | O24: 14.57 | P24: 11.08 | Q24: 9.32 | R24: 7.85 | S24: 5.78 | T24: 3.58 | U24: 2.46 | V24: 0.98 | W24: 0.4 | X24: 0.16 | Y24: 0.03
A25: Capital Expenditures | B25: -52.54 | C25: -32.25 | D25: -31.49 | E25: -24.64 | F25: -22.28 | G25: -23.55 | H25: -25.14 | I25: -13.18 | J25: -10.21 | K25: -9.95 | L25: -10.96 | M25: -7.36 | N25: -3.27 | O25: -3.44 | P25: -4.02 | Q25: -0.81 | R25: -2.36 | S25: -2.4 | T25: -1.9 | U25: -0.84 | V25: -0.36 | W25: -0.18 | X25: -0.04 | Y25: -0.01
A26: Net Investing Cash Flow | B26: -45.54 | C26: -27.06 | D26: -20.3 | E26: -35.52 | F26: -32.77 | G26: -29.49 | H26: -28.5 | I26: -31.4 | J26: -31.17 | K26: -23.71 | L26: -21.06 | M26: -13.68 | N26: -13.06 | O26: -19.04 | P26: -10.68 | Q26: -8.02 | R26: -5.32 | S26: -3.68 | T26: -6.9 | U26: -3.36 | V26: -1.9 | W26: -0.31 | X26: -0.11 | Y26: -0.03
A27: Net Financing Cash Flow | B27: -79.73 | C27: -72.09 | D27: -69.76 | E27: -61.36 | F27: -24.41 | G27: -23.21 | H27: -13.18 | I27: -8.3 | J27: -8.33 | K27: -4.23 | L27: -1.44 | M27: -0.86 | N27: 1.23 | O27: 0.81 | P27: 3.05 | Q27: 0.23 | R27: 0.09 | S27: 0.4 | T27: 2.97 | U27: 4.37 | V27: 1.19 | W27: 0.01 | X27: -0.01 | Y27: 0
A28: Free Cash Flow | B28: 72.76 | C28: 69.5 | D28: 60.01 | E28: 67.01 | F28: 42.84 | G28: 30.97 | H28: 22.83 | I28: 23.91 | J28: 25.82 | K28: 16.62 | L28: 11.42 | M28: 11.3 | N28: 13.35 | O28: 11.13 | P28: 7.06 | Q28: 8.51 | R28: 5.49 | S28: 3.37 | T28: 1.68 | U28: 1.62 | V28: 0.66 | W28: 0.22 | X28: 0.12 | Y28: 0.02
A29: Supplemental
A30: Stock Option Comp Exp (Net of Tax) | B30: 18.2 | C30: 17.6 | D30: 15.6 | E30: 12.6 | F30: 10.7 | G30: 10.79 | H30: 7.25 | I30: 6.07 | J30: 5.31 | K30: 3.6 | L30: 3.38 | M30: 1.96 | N30: 1.59 | O30: 1.18 | P30: 0.83 | Q30: 0.7 | R30: 0.67 | S30: 0.52 | T30: 0.27 | U30: 0.12 | V30: 0.17 | W30: 0.21
A31: Operating Lease Commitments | B31: 17.04 | C31: 17.68 | D31: 17.44 | E31: 15.46 | F31: 15.09 | G31: 10.1 | H31: 10.05 | I31: 8.75 | J31: 7.94 | L31: 6.25 | M31: 4.13 | N31: 3.7 | O31: 2.95 | P31: 2.39 | Q31: 2.54 | R31: 2.96 | S31: 2.28 | T31: 1.21 | U31: 0.69 | V31: 0.24 | W31: 0.15
A32: Long Term Debt Maturities | B32: 1.23 | C32: 1.36 | D32: 0.3 | E32: 0.11 | F32: 1.1 | G32: 0 | H32: 0 | I32: 0 | J32: 0 | K32: 1.23 | L32: 0.01 | M32: 1.01 | N32: 0 | O32: 0 | P32: 0 | Q32: 0 | R32: 0 | S32: 0 | T32: 0 | U32: 0 | V32: 0 | W32: 0 | X32: 0
A33: Audit Information
A34: Fees (M) | C34: 41.4 | D34: 41.22 | E34: 34.38 | F34: 29.85 | G34: 29.85 | H34: 27.45 | I34: 25.99 | J34: 20.96 | K34: 20.68 | L34: 20.86 | M34: 20.06 | N34: 14.29 | O34: 13.01 | R34: 12.03 | S34: 9.67 | T34: 8 | U34: 4.94 | V34: 3.76
A35: Opinion | B35: Unqualified | C35: Unqualified | D35: Unqualified | E35: Unqualified | F35: Unqualified | G35: Unqualified | H35: Unqualified | I35: Unqualified | J35: Unqualified | K35: Unqualified | L35: Unqualified | M35: Unqualified | N35: Unqualified | O35: Unqualified | P35: Unqualified | Q35: Unqualified | R35: Unqualified | S35: Unqualified | T35: Unqualified | U35: Unqualified | V35: Unqualified | W35: Unqualified | X35: Unqualified | Y35: Unqualified
A36: All figures in billions of U.S. Dollar except labeled items.

Sheet Ratios Factset
A1: Alphabet Inc. Class A (GOOGL)
A2: $147.50
A5: Alphabet Inc. Class A
A6: GOOGL 02079K305 BYVY8G0 NASDAQ Common stock
A7: Source: FactSet Fundamentals
B8: DEC '24 | C8: DEC '23 | D8: DEC '22 | E8: DEC '21 | F8: DEC '20 | G8: DEC '19 | H8: DEC '18 | I8: DEC '17 | J8: DEC '16 | K8: DEC '15 | L8: DEC '14 | M8: DEC '13 | N8: DEC '12 | O8: DEC '11 | P8: DEC '10 | Q8: DEC '09 | R8: DEC '08 | S8: DEC '07 | T8: DEC '06 | U8: DEC '05 | V8: DEC '04 | W8: DEC '03 | X8: DEC '02 | Y8: DEC '01
K9: Restate | L9: Restate
A10: Profitability
A11: Gross Margin | B11: 58,18 | C11: 56,75 | D11: 55,07 | E11: 56,91 | F11: 53,53 | G11: 55,46 | H11: 56,52 | I11: 58,94 | J11: 60,84 | K11: 61,73 | L11: 61,55 | M11: 56,77 | N11: 58,96 | O11: 65,17 | P11: 64,22 | Q11: 62,08 | R11: 60,44 | S11: 59,93 | T11: 60,16 | U11: 58,11 | V11: 54,29 | W11: 57,31 | X11: 70,08 | Y11: 83,54
A12: SG&A to Sales | B12: 26,11 | C12: 28,70 | D12: 29,12 | E12: 26,40 | F12: 31,02 | G12: 33,48 | H12: 33,50 | I12: 32,78 | J12: 35,01 | K12: 37,32 | L12: 36,17 | M12: 33,34 | N12: 32,70 | O12: 32,95 | P12: 29,27 | Q12: 27,84 | R12: 30,02 | S12: 29,29 | T12: 26,30 | U12: 23,42 | V12: 27,56 | W12: 33,95 | X12: 22,73 | Y12: 56,52
A13: Operating Margin | B13: 32,07 | C13: 28,05 | D13: 25,95 | E13: 30,51 | F13: 22,51 | G13: 21,98 | H13: 23,02 | I13: 26,17 | J13: 25,83 | K13: 24,41 | L13: 25,37 | M13: 23,43 | N13: 26,26 | O13: 32,22 | P13: 34,95 | Q13: 34,24 | R13: 30,43 | S13: 30,64 | T13: 33,86 | U13: 33,22 | V13: 26,73 | W13: 23,36 | X13: 42,43 | Y13: 12,69
A14: Pretax Margin | B14: 34,25 | C14: 27,91 | D14: 25,39 | E14: 35,24 | F14: 26,37 | G14: 24,55 | H14: 25,49 | I14: 24,49 | J14: 26,91 | K14: 26,70 | L14: 26,22 | M14: 24,27 | N14: 26,79 | O14: 32,56 | P14: 37,08 | Q14: 35,93 | R14: 26,86 | S14: 34,19 | T14: 37,82 | U14: 34,89 | V14: 20,39 | W14: 23,65 | X14: 42,07 | Y14: 11,65
A15: Net Margin | B15: 28,62 | C15: 24,03 | D15: 21,35 | E15: 29,53 | F15: 22,08 | G15: 21,28 | H15: 22,44 | I15: 11,40 | J15: 21,71 | K15: 21,51 | L15: 20,69 | M15: 20,45 | N15: 21,59 | O15: 25,72 | P15: 29,21 | Q15: 27,95 | R15: 19,39 | S15: 25,33 | T15: 29,02 | U15: 23,87 | V15: 12,51 | W15: 7,21 | X15: 22,67 | Y15: 8,08
A16: Free Cash Flow Margin | B16: 20,80 | C16: 22,63 | D16: 21,37 | E16: 26,03 | F16: 23,49 | G16: 19,19 | H16: 16,67 | I16: 21,53 | J16: 28,78 | K16: 22,59 | L16: 17,34 | M16: 18,92 | N16: 26,71 | O16: 29,39 | P16: 24,26 | Q16: 36,47 | R16: 25,21 | S16: 20,32 | T16: 15,82 | U16: 26,41 | V16: 20,63 | W16: 14,91 | X16: 26,86 | Y16: 20,86
A17: Capex To Sales | B17: 15,02 | C17: 10,50 | D17: 11,21 | E17: 9,57 | F17: 12,22 | G17: 14,59 | H17: 18,36 | I17: 11,87 | J17: 11,38 | K17: 13,52 | L17: 16,65 | M17: 12,32 | N17: 6,55 | O17: 9,08 | P17: 13,80 | Q17: 3,47 | R17: 10,82 | S17: 14,48 | T17: 17,94 | U17: 13,65 | V17: 11,16 | W17: 12,06 | X17: 8,46 | Y17: 15,11
A18: Return on Assets | B18: 23,48 | C18: 19,23 | D18: 16,55 | E18: 22,40 | F18: 13,52 | G18: 13,50 | H18: 14,29 | I18: 6,94 | J18: 12,37 | K18: 11,44 | L18: 11,34 | M18: 11,93 | N18: 12,97 | O18: 14,93 | P18: 17,30 | Q18: 18,05 | R18: 14,80 | S18: 19,19 | T18: 21,41 | U18: 21,59 | V18: 19,08 | W18: 17,97 | X18: 52,58
A19: Return on Equity | B19: 32,91 | C19: 27,36 | D19: 23,62 | E19: 32,07 | F19: 19,00 | G19: 18,12 | H19: 18,62 | I19: 8,69 | J19: 15,02 | K19: 14,12 | L19: 14,25 | M19: 15,36 | N19: 16,61 | O19: 18,66 | P19: 20,68 | Q19: 20,30 | R19: 16,60 | S19: 21,16 | T19: 23,26 | U19: 23,73 | V19: 22,57 | W19: 26,44 | X19: 82,27
A20: Return on Common Equity | B20: 32,91 | C20: 27,36 | D20: 23,62 | E20: 32,07 | F20: 19,00 | G20: 18,12 | H20: 18,62 | I20: 8,69 | J20: 15,02 | K20: 14,12 | L20: 14,25 | M20: 15,36 | N20: 16,61 | O20: 18,66 | P20: 20,68 | Q20: 20,30 | R20: 16,60 | S20: 21,16 | T20: 23,26 | U20: 23,73 | V20: 22,95 | W20: 28,52 | X20: 82,27
A21: Return on Total Capital | B21: 33,66 | C21: 28,74 | D21: 25,74 | E21: 29,62 | F21: 17,55 | G21: 17,78 | H21: 18,65 | I21: 19,40 | J21: 17,26 | K21: 15,31 | L21: 16,57 | M21: 16,48 | N21: 18,79 | O21: 21,77 | P21: 23,75 | Q21: 24,87 | R21: 26,04 | S21: 25,60 | T21: 27,14 | U21: 33,02 | V21: 48,10 | W21: 83,88
A22: Return on Invested Capital | B22: 30,42 | C22: 24,91 | D22: 21,37 | E22: 28,94 | F22: 17,36 | G22: 17,26 | H22: 18,18 | I22: 8,46 | J22: 14,68 | K22: 13,80 | L22: 13,85 | M22: 14,87 | N22: 15,88 | O22: 18,14 | P22: 20,68 | Q22: 20,30 | R22: 16,60 | S22: 21,16 | T22: 23,26 | U22: 23,73 | V22: 22,56 | W22: 26,16
A23: Cash Flow Return on Invested Capital | B23: 38,07 | C23: 34,35 | D23: 32,61 | E23: 34,88 | F23: 28,08 | G23: 27,41 | H23: 28,38 | I23: 24,77 | J23: 27,17 | K23: 23,17 | L23: 22,76 | M23: 22,72 | N23: 24,47 | O23: 27,13 | P23: 26,95 | Q23: 29,00 | R23: 30,84 | S23: 29,07 | T23: 27,06 | U23: 39,84 | V23: 55,23 | W23: 97,94
A24: Valuation
A25: Price/Sales | B25: 6,74 | C25: 5,79 | D25: 4,13 | E25: 7,62 | F25: 6,60 | G25: 5,80 | H25: 5,37 | I25: 6,68 | J25: 6,17 | K25: 7,33 | L25: 5,54 | M25: 6,36 | N25: 4,71 | O25: 5,58 | P25: 6,59 | Q25: 8,49 | R25: 4,48 | S25: 13,18 | T25: 13,44 | U25: 19,73 | V25: 16,49
A26: Price/Earnings | B26: 23,53 | C26: 24,08 | D26: 19,36 | E26: 25,82 | F26: 29,90 | G26: 27,24 | H26: 23,91 | I26: 58,54 | J26: 28,43 | K26: 34,06 | L26: 27,22 | M26: 31,22 | N26: 21,89 | O26: 21,70 | P26: 22,58 | Q26: 30,38 | R26: 23,11 | S26: 52,03 | T26: 46,33 | U26: 82,66 | V26: 132,18
A27: Price/Book Value | B27: 7,11 | C27: 6,14 | D27: 4,43 | E27: 7,62 | F27: 5,32 | G27: 4,58 | H27: 4,09 | I27: 4,80 | J27: 3,94 | K27: 4,44 | L27: 3,48 | M27: 4,31 | N27: 3,25 | O27: 3,61 | P27: 4,13 | Q27: 5,47 | R27: 3,43 | S27: 9,54 | T27: 8,35 | U27: 12,89 | V27: 18,07
A28: Price/Tangible Book Value | B28: 7,88 | C28: 6,85 | D28: 5,04 | E28: 8,44 | F28: 5,92 | G28: 5,16 | H28: 4,61 | I28: 5,50 | J28: 4,59 | K28: 5,31 | L28: 4,31 | M28: 5,40 | N28: 4,35 | O28: 4,26 | P28: 4,90 | Q28: 6,50 | R28: 4,33 | S28: 10,85 | T28: 9,39 | U28: 13,28 | V28: 19,35
A29: Price/Cash Flow | B29: 18,80 | C29: 17,47 | D29: 12,69 | E29: 21,42 | F29: 18,49 | G29: 17,16 | H29: 15,32 | I29: 19,98 | J29: 15,36 | K29: 20,29 | L29: 16,29 | M29: 20,35 | N29: 14,14 | O29: 14,51 | P29: 17,33 | Q29: 21,26 | R29: 12,44 | S29: 37,86 | T29: 39,81 | U29: 49,23 | V29: 53,83
A30: Price/Free Cash Flow | B30: 32,38 | C30: 25,57 | D30: 19,35 | E30: 29,30 | F30: 28,11 | G30: 30,21 | H30: 32,19 | I30: 31,00 | J30: 21,44 | K30: 32,43 | L30: 31,93 | M30: 33,60 | N30: 17,61 | O30: 18,99 | P30: 27,18 | Q30: 23,28 | R30: 17,78 | S30: 64,83 | T30: 84,96 | U30: 74,69 | V30: 79,92
A31: Dividend Yield (%) | B31: 0,32 | C31: 0,00 | D31: 0,00 | E31: 0,00 | F31: 0,00 | G31: 0,00 | H31: 0,00 | I31: 0,00 | J31: 0,00 | K31: 0,00 | L31: 0,00 | M31: 0,00 | N31: 0,00 | O31: 0,00 | P31: 0,00 | Q31: 0,00 | R31: 0,00 | S31: 0,00 | T31: 0,00 | U31: 0,00 | V31: 0,00
A32: Enterprise Value/EBIT | B32: 20,00 | C32: 19,26 | D32: 14,41 | E32: 23,00 | F32: 26,18 | G32: 23,07 | H32: 19,72 | I32: 21,82 | J32: 20,08 | K32: 26,00 | L32: 18,07 | M32: 23,07 | N32: 14,55 | O32: 13,89 | P32: 15,65 | Q32: 21,60 | R32: 12,23 | S32: 39,76 | T32: 36,49 | U32: 55,60 | V32: 59,57
A33: Enterprise Value/EBITDA | B33: 17,60 | C33: 16,92 | D33: 11,82 | E33: 19,86 | F33: 19,63 | G33: 17,32 | H33: 15,33 | I33: 17,63 | J33: 15,87 | K33: 20,28 | L33: 14,16 | M33: 18,01 | N33: 11,87 | O33: 12,06 | P33: 13,77 | Q33: 18,14 | R33: 9,97 | S33: 33,40 | T33: 31,48 | U33: 48,60 | V33: 50,73
A34: Enterprise Value/Sales | B34: 6,42 | C34: 5,40 | D34: 3,74 | E34: 7,02 | F34: 5,89 | G34: 5,07 | H34: 4,54 | I34: 5,71 | J34: 5,19 | K34: 6,34 | L34: 4,58 | M34: 5,41 | N34: 3,82 | O34: 4,47 | P34: 5,47 | Q34: 7,40 | R34: 3,72 | S34: 12,18 | T34: 12,36 | U34: 18,47 | V34: 15,92
A35: Total Debt/Enterprise Value | B35: 0,01 | C35: 0,02 | D35: 0,03 | E35: 0,02 | F35: 0,03 | G35: 0,02 | H35: 0,01 | I35: 0,01 | J35: 0,01 | K35: 0,01 | L35: 0,02 | M35: 0,02 | N35: 0,03 | O35: 0,02 | P35: 0,02 | Q35: 0,00 | R35: 0,00 | S35: 0,00 | T35: 0,00 | U35: 0,00 | V35: 0,00
A36: Per Share
A37: Sales per Share | B37: 28,10 | C37: 24,14 | D37: 21,34 | E37: 19,00 | F37: 13,27 | G37: 11,55 | H37: 9,74 | I37: 7,89 | J37: 6,42 | K37: 5,31 | L37: 4,79 | M37: 4,41 | N37: 3,76 | O37: 2,90 | P37: 2,25 | Q37: 1,83 | R37: 1,72 | S37: 1,31 | T37: 0,86 | U37: 0,53 | V37: 0,29 | W37: 0,13 | X37: 0,05 | Y37: 0,01
A38: EBIT (Operating Income) per Share | B38: 9,01 | C38: 6,77 | D38: 5,54 | E38: 5,80 | F38: 2,99 | G38: 2,54 | H38: 2,24 | I38: 2,06 | J38: 1,66 | K38: 1,30 | L38: 1,22 | M38: 1,03 | N38: 0,99 | O38: 0,93 | P38: 0,79 | Q38: 0,63 | R38: 0,52 | S38: 0,40 | T38: 0,29 | U38: 0,17 | V38: 0,08 | W38: 0,03 | X38: 0,02 | Y38: 0,00
A39: EPS (recurring) | B39: 7,81 | C39: 5,92 | D39: 4,73 | E39: 5,07 | F39: 2,67 | G39: 2,40 | H39: 2,23 | I39: 1,04 | J39: 1,41 | K39: 1,16 | L39: 1,00 | M39: 0,90 | N39: 0,87 | O39: 0,79 | P39: 0,68 | Q39: 0,52 | R39: 0,39 | S39: 0,33 | T39: 0,32 | U39: 0,13 | V39: 0,05 | W39: 0,01 | X39: 0,01 | Y39: 0,00
A40: EPS (basic) | B40: 8,13 | C40: 5,84 | D40: 4,59 | E40: 5,69 | F40: 2,96 | G40: 2,48 | H40: 2,21 | I40: 0,91 | J40: 1,42 | K40: 1,16 | L40: 0,99 | M40: 0,91 | N40: 0,82 | O40: 0,76 | P40: 0,67 | Q40: 0,52 | R40: 0,34 | S40: 0,34 | T40: 0,26 | U40: 0,13 | V40: 0,05 | W40: 0,01 | X40: 0,01 | Y40: 0,00
A41: EPS (diluted) | B41: 8,04 | C41: 5,80 | D41: 4,56 | E41: 5,61 | F41: 2,93 | G41: 2,46 | H41: 2,19 | I41: 0,90 | J41: 1,39 | K41: 1,14 | L41: 0,97 | M41: 0,90 | N41: 0,81 | O41: 0,74 | P41: 0,66 | Q41: 0,51 | R41: 0,33 | S41: 0,33 | T41: 0,25 | U41: 0,13 | V41: 0,04 | W41: 0,01 | X41: 0,01 | Y41: 0,00
A42: Dividends per Share | B42: 0,60 | C42: 0,00 | D42: 0,00 | E42: 0,00 | F42: 0,00 | G42: 0,00 | H42: 0,00 | I42: 0,00 | J42: 0,00 | K42: 0,00 | L42: 0,00 | M42: 0,00 | N42: 0,00 | O42: 0,00 | P42: 0,00 | Q42: 0,00 | R42: 0,00 | S42: 0,00 | T42: 0,00 | U42: 0,00 | V42: 0,00
...

Sheet M&A Deals
A1: Alphabet Inc. Class C (GOOG) $160.89
A3: All M&A Deals (498)
A4: Announce Date | B4: Close Date | C4: Target | D4: Acquirer | E4: Deal Type | F4: Transaction Value | G4: EV/EBITDA | H4: Role | I4: Target Industry
A5: 18 Mar '25 | B5: Pending | C5: Wiz, Inc. (United States) | D5: Google LLC | E5: Acquisition / Merger | F5: 32000 | G5: - | H5: Buyer | I5: Packaged Software
A6: 06 Feb '25 | B6: 06 Feb '25 | C6: Caraway, Inc. | D6: Summer Health, Inc. | E6: Acquisition / Merger | F6: - | G6: - | H6: Seller | I6: Packaged Software
A7: 22 Jan '25 | B7: Pending | C7: HTC Corp. /XR Business/ | D7: Google LLC | E7: Acquisition / Merger | F7: 250 | G7: - | H7: Buyer | I7: Miscellaneous Commercial Services
A8: 10 Jan '25 | B8: Pending | C8: Machinify, Inc. | D8: New Mountain Capital LLC | E8: Acquisition / Merger | F8: - | G8: - | H8: Seller | I8: Packaged Software
A9: 20 Nov '24 | B9: 20 Nov '24 | C9: Odoo SA | D9: Private Equity Group | E9: Minority Stake | F9: 529.3 | G9: 12.9 | H9: Buyer | I9: Packaged Software
A10: 23 Jul '24 | B10: 23 Jul '24 | C10: Planck Resolution Ltd. | D10: Applied Systems, Inc. | E10: Acquisition / Merger | F10: 300 | G10: - | H10: Buyer | I10: Packaged Software
A11: 14 Jul '24 | B11: Rumor Cancelled | C11: Wiz, Inc. (United States) | D11: Alphabet, Inc. | E11: Acquisition / Merger | F11: 23000 | G11: - | H11: Buyer | I11: Packaged Software
A12: 05 Jun '24 | B12: 05 Jun '24 | C12: Cameyo, Inc. | D12: Google LLC | E12: Acquisition / Merger | F12: - | G12: - | H12: Buyer | I12: Packaged Software
A13: 29 May '24 | B13: 29 May '24 | C13: Lotus Software, Inc. | D13: Chameleon Intelligent Tech, Inc. | E13: Acquisition / Merger | F13: - | G13: - | H13: Seller | I13: Packaged Software
A14: 04 Apr '24 | B14: Rumor Cancelled | C14: HubSpot, Inc. | D14: Alphabet, Inc. | E14: Acquisition / Merger | F14: - | G14: - | H14: Buyer | I14: Packaged Software
A15: 31 Aug '23 | B15: 31 Aug '23 | C15: Fyyne, Inc. | D15: Salescabal, Inc. | E15: Acquisition / Merger | F15: - | G15: - | H15: Seller | I15: Packaged Software
A16: 24 Aug '23 | B16: 24 Aug '23 | C16: Equalum Ltd. | D16: Google LLC | E16: Acquisition / Merger | F16: - | G16: - | H16: Buyer | I16: Data Processing Services
A17: 17 Aug '23 | B17: 31 Mar '24 | C17: TeamSystem Holdco SpA | D17: Private Equity Group | E17: Minority Stake | F17: - | G17: - | H17: Buyer | I17: Packaged Software
A18: 15 Jun '23 | B18: 07 Sep '23 | C18: Google LLC /Domains Business/ | D18: Squarespace, Inc. | E18: Acquisition / Merger | F18: - | G18: - | H18: Seller | I18: Packaged Software
A19: 21 Feb '23 | B19: 28 Mar '23 | C19: Photomath, Inc. | D19: Google LLC | E19: Acquisition / Merger | F19: - | G19: - | H19: Buyer | I19: Internet Software/Services
A20: 17 Dec '22 | B20: 17 Dec '22 | C20: Korulab, Inc. | D20: Google LLC | E20: Acquisition / Merger | F20: - | G20: - | H20: Buyer | I20: Packaged Software
A21: 14 Dec '22 | B21: 14 Dec '22 | C21: Open Robotics LLC | D21: Intrinsic Innovation LLC | E21: Majority Stake | F21: - | G21: - | H21: Buyer | I21: Information Technology Services
A22: 06 Dec '22 | B22: 06 Dec '22 | C22: Riskhandler Solutions Ltd. | D22: Applied Systems, Inc. | E22: Acquisition / Merger | F22: - | G22: - | H22: Buyer | I22: Packaged Software
A23: 27 Oct '22 | B23: 27 Oct '22 | C23: Omnipresence, Inc. /Facemoji/ | D23: Google LLC | E23: Acquisition / Merger | F23: 100 | G23: - | H23: Buyer | I23: Packaged Software
A24: 26 Oct '22 | B24: 26 Oct '22 | C24: Sound Life Sciences, Inc. | D24: Google LLC | E24: Acquisition / Merger | F24: - | G24: - | H24: Buyer | I24: Packaged Software
A25: 11 Oct '22 | B25: 11 Oct '22 | C25: BrightBytes, Inc. | D25: Google LLC | E25: Acquisition / Merger | F25: - | G25: - | H25: Buyer | I25: Packaged Software
A26: 29 Sep '22 | B26: 29 Sep '22 | C26: Verily Life Sciences LLC | D26: Swiss Re AG | E26: Minority Stake | F26: - | G26: - | H26: Seller | I26: Packaged Software
A27: 20 Sep '22 | B27: 20 Sep '22 | C27: BreezoMeter Ltd. | D27: Google LLC | E27: Acquisition / Merger | F27: 250 | G27: - | H27: Buyer | I27: Information Technology Services
A28: 20 Sep '22 | B28: 20 Sep '22 | C28: Phiar Technologies, Inc. | D28: Google LLC | E28: Acquisition / Merger | F28: - | G28: - | H28: Buyer | I28: Packaged Software
A29: 16 Aug '22 | B29: 16 Aug '22 | C29: Tarmika, Inc. | D29: Applied Systems, Inc. | E29: Acquisition / Merger | F29: - | G29: - | H29: Buyer | I29: Packaged Software
A30: 04 May '22 | B30: 04 May '22 | C30: Raxium, Inc. | D30: Google LLC | E30: Acquisition / Merger | F30: 1000 | G30: 15957.9 | H30: Buyer | I30: Electrical Products
A31: 29 Apr '22 | B31: 29 Apr '22 | C31: MobiledgeX, Inc. | D31: Google Cloud | E31: Acquisition / Merger | F31: - | G31: - | H31: Buyer | I31: Packaged Software
A32: 23 Apr '22 | B32: 23 Apr '22 | C32: Vicarious FPC, Inc. | D32: Intrinsic Innovation LLC | E32: Acquisition / Merger | F32: - | G32: - | H32: Buyer | I32: Packaged Software
A33: 08 Mar '22 | B33: 12 Sep '22 | C33: Mandiant, Inc. | D33: Google LLC | E33: Acquisition / Merger | F33: 4700.5 | G33: -20.7 | H33: Buyer | I33: Information Technology Services
A34: 13 Jan '22 | B34: 13 Jan '22 | C34: Linden Research, Inc. | D34: High Fidelity, Inc. | E34: Majority Stake | F34: - | G34: - | H34: Buyer | I34: Packaged Software
A35: 13 Jan '22 | B35: 13 Jan '22 | C35: Tomorrow Ideas, Inc. | D35: Ethos Technologies, Inc. | E35: Acquisition / Merger | F35: - | G35: - | H35: Buyer | I35: Packaged Software
A36: 04 Jan '22 | B36: 04 Jan '22 | C36: CyArx Technologies Ltd. | D36: Google LLC | E36: Acquisition / Merger | F36: 500 | G36: - | H36: Buyer | I36: Information Technology Services
A37: 17 Nov '21 | B37: 17 Nov '21 | C37: TAP Sound System SAS | D37: Google France SARL | E37: Acquisition / Merger | F37: - | G37: - | H37: Buyer | I37: Packaged Software
A38: 20 Oct '21 | B38: 20 Oct '21 | C38: Compilerworks, Inc. | D38: Google LLC | E38: Acquisition / Merger | F38: - | G38: - | H38: Buyer | I38: Packaged Software
A39: 18 Oct '21 | B39: 18 Oct '21 | C39: MuJoCo | D39: DeepMind Technologies Ltd. | E39: Acquisition / Merger | F39: - | G39: - | H39: Buyer | I39: Miscellaneous Commercial Services
A40: 30 Sep '21 | B40: 30 Sep '21 | C40: Loon LLC /Intellectual Property & Patents/ | D40: Aerostar International LLC | E40: Acquisition / Merger | F40: - | G40: - | H40: Seller | I40: Miscellaneous Commercial Services
A41: 30 Sep '21 | B41: 30 Sep '21 | C41: Boston Polarimetrics, Inc. | D41: Vicarious FPC, Inc. | E41: Acquisition / Merger | F41: - | G41: - | H41: Buyer | I41: Packaged Software
...

Sheet Annual reports
S6: 2009 | T6: 108204000
S7: 2008 | T7: 3320299000
S8: 2007 | T8: 906651000
S9: 2006 | T9: 402446000
S10: 2005 | T10: 101310000
S11: 2004 | T11: 58863000
N25: https://materials.proxyvote.com/Approved/38259P/20100315/AR_56325/HTML2/google-ar2009_0082.htm
N26: 2009
A28: https://abc.xyz/assets/77/51/9841ad5c4fbe85b4440c47a4df8d/goog-10-k-2024.pdf | G28: https://abc.xyz/assets/43/44/675b83d7455885c4615d848d52a4/goog-10-k-2023.pdf | L28: GOOG 10-K 2023
A29: GOOG 10-K 2024
A31: https://abc.xyz/assets/d4/4f/a48b94d548d0b2fdc029a95e8c63/2022-alphabet-annual-report.pdf | G31: 2022-alphabet-annual-report.pdf
U32: https://abc.xyz/assets/investor/static/pdf/2007_google_annual_report.pdf | Z32: 2007
A33: https://abc.xyz/assets/investor/static/pdf/2021_alphabet_annual_report.pdf | G33: GOOG019_Alphabet_2021-Annual-Report_Web.pdf
A35: https://abc.xyz/assets/51/9a/52377a1f4b268cab701bbde10ce9/2020-alphabet-annual-report.pdf | G35: Rev2_210419_YIR_Cover.indd | R35: https://www.sec.gov/Archives/edgar/data/1288776/000119312506056598/d10k.htm#fin75474_5
R36: 2005
A37: https://abc.xyz/assets/investor/static/pdf/2019_alphabet_annual_report.pdf | G37: 2019
A39: https://abc.xyz/assets/investor/static/pdf/20180204_alphabet_10K.pdf | G39: 2018
A41: https://abc.xyz/assets/investor/static/pdf/20171231_alphabet_10K.pdf | G41: 2017
A43: https://abc.xyz/assets/investor/static/pdf/2016_google_annual_report.pdf | G43: 2016
A45: https://abc.xyz/assets/investor/static/pdf/2015_alphabet_annual_report.pdf | G45: 2015
A47: https://abc.xyz/assets/investor/static/pdf/2014_google_annual_report.pdf | G47: 2014
A49: https://abc.xyz/assets/investor/static/pdf/20131231_google_10K.pdf | G49: 2013
A51: https://abc.xyz/assets/investor/static/pdf/20101231_google_10K.pdf | G51: 2010
